<?xml version="1.0" encoding="UTF-8"?>
<testng-results skipped="0" failed="1" total="1" passed="0">
  <reporter-output>
  </reporter-output>
  <suite name="Default suite" duration-ms="11252" started-at="2019-06-28T22:38:42Z" finished-at="2019-06-28T22:38:53Z">
    <groups>
    </groups>
    <test name="Default test" duration-ms="11252" started-at="2019-06-28T22:38:42Z" finished-at="2019-06-28T22:38:53Z">
      <class name="zapi.prototytpe.MyvestFailTest">
        <test-method status="PASS" signature="setup()[pri:0, instance:zapi.prototytpe.MyvestFailTest@5e3a8624]" name="setup" is-config="true" duration-ms="8467" started-at="2019-06-28T15:38:42Z" finished-at="2019-06-28T15:38:50Z">
          <reporter-output>
          </reporter-output>
        </test-method> <!-- setup -->
        <test-method status="FAIL" signature="myVestLoginTest()[pri:0, instance:zapi.prototytpe.MyvestFailTest@5e3a8624]" name="myVestLoginTest" duration-ms="1323" started-at="2019-06-28T15:38:50Z" finished-at="2019-06-28T15:38:52Z">
          <exception class="java.lang.AssertionError">
            <message>
              <![CDATA[expected [https://tiaa.uatcan.myvest.com/u/] but found [https://tiaa.uatcan.myvest.com/u/1]]]>
            </message>
            <full-stacktrace>
              <![CDATA[java.lang.AssertionError: expected [https://tiaa.uatcan.myvest.com/u/] but found [https://tiaa.uatcan.myvest.com/u/1]
	at org.testng.Assert.fail(Assert.java:94)
	at org.testng.Assert.failNotEquals(Assert.java:494)
	at org.testng.Assert.assertEquals(Assert.java:123)
	at org.testng.Assert.assertEquals(Assert.java:176)
	at org.testng.Assert.assertEquals(Assert.java:186)
	at zapi.prototytpe.MyvestFailTest.myVestLoginTest(MyvestFailTest.java:52)
	at sun.reflect.NativeMethodAccessorImpl.invoke0(Native Method)
	at sun.reflect.NativeMethodAccessorImpl.invoke(NativeMethodAccessorImpl.java:62)
	at sun.reflect.DelegatingMethodAccessorImpl.invoke(DelegatingMethodAccessorImpl.java:43)
	at java.lang.reflect.Method.invoke(Method.java:498)
	at org.testng.internal.MethodInvocationHelper.invokeMethod(MethodInvocationHelper.java:84)
	at org.testng.internal.Invoker.invokeMethod(Invoker.java:714)
	at org.testng.internal.Invoker.invokeTestMethod(Invoker.java:901)
	at org.testng.internal.Invoker.invokeTestMethods(Invoker.java:1231)
	at org.testng.internal.TestMethodWorker.invokeTestMethods(TestMethodWorker.java:127)
	at org.testng.internal.TestMethodWorker.run(TestMethodWorker.java:111)
	at org.testng.TestRunner.privateRun(TestRunner.java:767)
	at org.testng.TestRunner.run(TestRunner.java:617)
	at org.testng.SuiteRunner.runTest(SuiteRunner.java:348)
	at org.testng.SuiteRunner.runSequentially(SuiteRunner.java:343)
	at org.testng.SuiteRunner.privateRun(SuiteRunner.java:305)
	at org.testng.SuiteRunner.run(SuiteRunner.java:254)
	at org.testng.SuiteRunnerWorker.runSuite(SuiteRunnerWorker.java:52)
	at org.testng.SuiteRunnerWorker.run(SuiteRunnerWorker.java:86)
	at org.testng.TestNG.runSuitesSequentially(TestNG.java:1224)
	at org.testng.TestNG.runSuitesLocally(TestNG.java:1149)
	at org.testng.TestNG.run(TestNG.java:1057)
	at org.testng.remote.AbstractRemoteTestNG.run(AbstractRemoteTestNG.java:115)
	at org.testng.remote.RemoteTestNG.initAndRun(RemoteTestNG.java:251)
	at org.testng.remote.RemoteTestNG.main(RemoteTestNG.java:77)
]]>
            </full-stacktrace>
          </exception> <!-- java.lang.AssertionError -->
          <reporter-output>
          </reporter-output>
        </test-method> <!-- myVestLoginTest -->
        <test-method status="PASS" signature="tearDown()[pri:0, instance:zapi.prototytpe.MyvestFailTest@5e3a8624]" name="tearDown" is-config="true" duration-ms="1450" started-at="2019-06-28T15:38:52Z" finished-at="2019-06-28T15:38:53Z">
          <reporter-output>
          </reporter-output>
        </test-method> <!-- tearDown -->
      </class> <!-- zapi.prototytpe.MyvestFailTest -->
    </test> <!-- Default test -->
  </suite> <!-- Default suite -->
</testng-results>
